nohup: ignoring input
[I 2024-09-29 15:30:38.143 ServerApp] jupyter_lsp | extension was successfully linked.
[I 2024-09-29 15:30:38.157 ServerApp] jupyter_server_terminals | extension was successfully linked.
[I 2024-09-29 15:30:38.174 ServerApp] jupyterlab | extension was successfully linked.
[I 2024-09-29 15:30:38.177 ServerApp] Writing Jupyter server cookie secret to /home/ec2-user/.local/share/jupyter/runtime/jupyter_cookie_secret
[I 2024-09-29 15:30:38.978 ServerApp] notebook_shim | extension was successfully linked.
[I 2024-09-29 15:30:39.026 ServerApp] notebook_shim | extension was successfully loaded.
[I 2024-09-29 15:30:39.030 ServerApp] jupyter_lsp | extension was successfully loaded.
[I 2024-09-29 15:30:39.032 ServerApp] jupyter_server_terminals | extension was successfully loaded.
[I 2024-09-29 15:30:39.036 LabApp] JupyterLab extension loaded from /home/ec2-user/environment/jupyterlab-venv/lib64/python3.9/site-packages/jupyterlab
[I 2024-09-29 15:30:39.036 LabApp] JupyterLab application directory is /home/ec2-user/environment/jupyterlab-venv/share/jupyter/lab
[I 2024-09-29 15:30:39.037 LabApp] Extension Manager is 'pypi'.
[I 2024-09-29 15:30:39.049 ServerApp] jupyterlab | extension was successfully loaded.
[I 2024-09-29 15:30:39.050 ServerApp] Serving notebooks from local directory: /home/ec2-user/environment
[I 2024-09-29 15:30:39.050 ServerApp] Jupyter Server 2.14.2 is running at:
[I 2024-09-29 15:30:39.050 ServerApp] http://ip-10-0-2-22.ec2.internal:8888/lab?token=88de32360a91cd67a4c1bd44687af65e89fb9d149ea510f5
[I 2024-09-29 15:30:39.050 ServerApp]     http://127.0.0.1:8888/lab?token=88de32360a91cd67a4c1bd44687af65e89fb9d149ea510f5
[I 2024-09-29 15:30:39.050 ServerApp] Use Control-C to stop this server and shut down all kernels (twice to skip confirmation).
[W 2024-09-29 15:30:39.060 ServerApp] No web browser found: Error('could not locate runnable browser').
[C 2024-09-29 15:30:39.061 ServerApp] 
    
    To access the server, open this file in a browser:
        file:///home/ec2-user/.local/share/jupyter/runtime/jpserver-2481-open.html
    Or copy and paste one of these URLs:
        http://ip-10-0-2-22.ec2.internal:8888/lab?token=88de32360a91cd67a4c1bd44687af65e89fb9d149ea510f5
        http://127.0.0.1:8888/lab?token=88de32360a91cd67a4c1bd44687af65e89fb9d149ea510f5
[I 2024-09-29 15:30:39.673 ServerApp] Skipped non-installed server(s): bash-language-server, dockerfile-language-server-nodejs, javascript-typescript-langserver, jedi-language-server, julia-language-server, pyright, python-language-server, python-lsp-server, r-languageserver, sql-language-server, texlab, typescript-language-server, unified-language-server, vscode-css-languageserver-bin, vscode-html-languageserver-bin, vscode-json-languageserver-bin, yaml-language-server
[I 2024-09-29 15:31:54.121 LabApp] Build is up to date
[I 2024-09-29 15:32:21.371 ServerApp] Writing notebook-signing key to /home/ec2-user/.local/share/jupyter/notebook_secret
[W 2024-09-29 15:32:21.373 ServerApp] Notebook C2_W1_Lab_3_S3.ipynb is not trusted
[I 2024-09-29 15:32:22.473 ServerApp] Kernel started: 406db6cc-34d4-4855-993c-a988590d70e1
[I 2024-09-29 15:32:23.982 ServerApp] Connecting to kernel 406db6cc-34d4-4855-993c-a988590d70e1.
[I 2024-09-29 15:32:24.212 ServerApp] Connecting to kernel 406db6cc-34d4-4855-993c-a988590d70e1.
[I 2024-09-29 15:32:24.408 ServerApp] Connecting to kernel 406db6cc-34d4-4855-993c-a988590d70e1.
[I 2024-09-29 15:34:21.806 ServerApp] Saving file at /C2_W1_Lab_3_S3.ipynb
[I 2024-09-29 15:36:22.064 ServerApp] Saving file at /C2_W1_Lab_3_S3.ipynb
[I 2024-09-29 15:40:22.701 ServerApp] Saving file at /C2_W1_Lab_3_S3.ipynb
[I 2024-09-29 15:42:23.027 ServerApp] Saving file at /C2_W1_Lab_3_S3.ipynb
[I 2024-09-29 15:44:23.271 ServerApp] Saving file at /C2_W1_Lab_3_S3.ipynb
[I 2024-09-29 15:46:23.511 ServerApp] Saving file at /C2_W1_Lab_3_S3.ipynb
[I 2024-09-29 15:48:23.850 ServerApp] Saving file at /C2_W1_Lab_3_S3.ipynb
[I 2024-09-29 15:50:24.095 ServerApp] Saving file at /C2_W1_Lab_3_S3.ipynb
[E 2024-09-29 15:51:06.331 ServerApp] Uncaught exception in write_error
    Traceback (most recent call last):
      File "/home/ec2-user/environment/jupyterlab-venv/lib64/python3.9/site-packages/tornado/web.py", line 1753, in _execute
        raise HTTPError(405)
    tornado.web.HTTPError: HTTP 405: Method Not Allowed
    
    During handling of the above exception, another exception occurred:
    
    Traceback (most recent call last):
      File "/home/ec2-user/environment/jupyterlab-venv/lib64/python3.9/site-packages/tornado/web.py", line 1298, in send_error
        self.write_error(status_code, **kwargs)
      File "/home/ec2-user/environment/jupyterlab-venv/lib64/python3.9/site-packages/jupyter_server/base/handlers.py", line 739, in write_error
        html = self.render_template("%s.html" % status_code, **ns)
      File "/home/ec2-user/environment/jupyterlab-venv/lib64/python3.9/site-packages/jupyter_server/base/handlers.py", line 665, in render_template
        ns.update(self.template_namespace)
      File "/home/ec2-user/environment/jupyterlab-venv/lib64/python3.9/site-packages/jupyter_server/base/handlers.py", line 675, in template_namespace
        logged_in=self.logged_in,
      File "/home/ec2-user/environment/jupyterlab-venv/lib64/python3.9/site-packages/jupyter_server/base/handlers.py", line 198, in logged_in
        user = self.current_user
      File "/home/ec2-user/environment/jupyterlab-venv/lib64/python3.9/site-packages/tornado/web.py", line 1424, in current_user
        self._current_user = self.get_current_user()
      File "/home/ec2-user/environment/jupyterlab-venv/lib64/python3.9/site-packages/jupyter_server/base/handlers.py", line 177, in get_current_user
        raise RuntimeError(msg)
    RuntimeError: Calling `Template404.get_current_user()` directly is deprecated in jupyter-server 2.0. Use `self.current_user` instead (works in all versions).
[W 2024-09-29 15:51:06.333 ServerApp] 405 CONNECT azenv.0889.org:443 (@144.91.103.52) 2.48ms referer=None
[I 2024-09-29 15:52:24.333 ServerApp] Saving file at /C2_W1_Lab_3_S3.ipynb
[W 2024-09-29 15:52:51.449 ServerApp] Notebook C2_W1_Lab_3_S3_Solution.ipynb is not trusted
[I 2024-09-29 15:52:52.090 ServerApp] Kernel started: 640712e4-0027-4280-9d63-6da8f53af0ff
[I 2024-09-29 15:52:52.825 ServerApp] Connecting to kernel 640712e4-0027-4280-9d63-6da8f53af0ff.
[I 2024-09-29 15:54:24.562 ServerApp] Saving file at /C2_W1_Lab_3_S3.ipynb
[I 2024-09-29 15:54:51.753 ServerApp] Saving file at /C2_W1_Lab_3_S3_Solution.ipynb
[I 2024-09-29 15:56:24.790 ServerApp] Saving file at /C2_W1_Lab_3_S3.ipynb
[I 2024-09-29 15:58:25.040 ServerApp] Saving file at /C2_W1_Lab_3_S3.ipynb
[I 2024-09-29 16:00:25.285 ServerApp] Saving file at /C2_W1_Lab_3_S3.ipynb
[I 2024-09-29 16:06:26.696 ServerApp] Saving file at /C2_W1_Lab_3_S3.ipynb
[I 2024-09-29 16:08:26.934 ServerApp] Saving file at /C2_W1_Lab_3_S3.ipynb
[E 2024-09-29 16:10:00.509 ServerApp] Uncaught exception in write_error
    Traceback (most recent call last):
      File "/home/ec2-user/environment/jupyterlab-venv/lib64/python3.9/site-packages/tornado/web.py", line 1753, in _execute
        raise HTTPError(405)
    tornado.web.HTTPError: HTTP 405: Method Not Allowed
    
    During handling of the above exception, another exception occurred:
    
    Traceback (most recent call last):
      File "/home/ec2-user/environment/jupyterlab-venv/lib64/python3.9/site-packages/tornado/web.py", line 1298, in send_error
        self.write_error(status_code, **kwargs)
      File "/home/ec2-user/environment/jupyterlab-venv/lib64/python3.9/site-packages/jupyter_server/base/handlers.py", line 739, in write_error
        html = self.render_template("%s.html" % status_code, **ns)
      File "/home/ec2-user/environment/jupyterlab-venv/lib64/python3.9/site-packages/jupyter_server/base/handlers.py", line 665, in render_template
        ns.update(self.template_namespace)
      File "/home/ec2-user/environment/jupyterlab-venv/lib64/python3.9/site-packages/jupyter_server/base/handlers.py", line 675, in template_namespace
        logged_in=self.logged_in,
      File "/home/ec2-user/environment/jupyterlab-venv/lib64/python3.9/site-packages/jupyter_server/base/handlers.py", line 198, in logged_in
        user = self.current_user
      File "/home/ec2-user/environment/jupyterlab-venv/lib64/python3.9/site-packages/tornado/web.py", line 1424, in current_user
        self._current_user = self.get_current_user()
      File "/home/ec2-user/environment/jupyterlab-venv/lib64/python3.9/site-packages/jupyter_server/base/handlers.py", line 177, in get_current_user
        raise RuntimeError(msg)
    RuntimeError: Calling `Template404.get_current_user()` directly is deprecated in jupyter-server 2.0. Use `self.current_user` instead (works in all versions).
[W 2024-09-29 16:10:00.511 ServerApp] 405 CONNECT azenv.0889.org:443 (@144.91.103.52) 1.64ms referer=None
[I 2024-09-29 16:10:27.242 ServerApp] Saving file at /C2_W1_Lab_3_S3.ipynb
[I 2024-09-29 16:12:27.486 ServerApp] Saving file at /C2_W1_Lab_3_S3.ipynb
[I 2024-09-29 16:14:27.746 ServerApp] Saving file at /C2_W1_Lab_3_S3.ipynb
[I 2024-09-29 16:16:27.995 ServerApp] Saving file at /C2_W1_Lab_3_S3.ipynb
[I 2024-09-29 16:18:28.228 ServerApp] Saving file at /C2_W1_Lab_3_S3.ipynb
[I 2024-09-29 16:20:28.498 ServerApp] Saving file at /C2_W1_Lab_3_S3.ipynb
[I 2024-09-29 16:22:29.696 ServerApp] Saving file at /C2_W1_Lab_3_S3.ipynb
[I 2024-09-29 16:24:29.939 ServerApp] Saving file at /C2_W1_Lab_3_S3.ipynb
[I 2024-09-29 16:26:30.190 ServerApp] Saving file at /C2_W1_Lab_3_S3.ipynb
[I 2024-09-29 16:30:30.443 ServerApp] Saving file at /C2_W1_Lab_3_S3.ipynb
[I 2024-09-29 16:32:30.707 ServerApp] Saving file at /C2_W1_Lab_3_S3.ipynb
[E 2024-09-29 16:35:14.814 ServerApp] Uncaught exception in write_error
    Traceback (most recent call last):
      File "/home/ec2-user/environment/jupyterlab-venv/lib64/python3.9/site-packages/tornado/web.py", line 1753, in _execute
        raise HTTPError(405)
    tornado.web.HTTPError: HTTP 405: Method Not Allowed
    
    During handling of the above exception, another exception occurred:
    
    Traceback (most recent call last):
      File "/home/ec2-user/environment/jupyterlab-venv/lib64/python3.9/site-packages/tornado/web.py", line 1298, in send_error
        self.write_error(status_code, **kwargs)
      File "/home/ec2-user/environment/jupyterlab-venv/lib64/python3.9/site-packages/jupyter_server/base/handlers.py", line 739, in write_error
        html = self.render_template("%s.html" % status_code, **ns)
      File "/home/ec2-user/environment/jupyterlab-venv/lib64/python3.9/site-packages/jupyter_server/base/handlers.py", line 665, in render_template
        ns.update(self.template_namespace)
      File "/home/ec2-user/environment/jupyterlab-venv/lib64/python3.9/site-packages/jupyter_server/base/handlers.py", line 675, in template_namespace
        logged_in=self.logged_in,
      File "/home/ec2-user/environment/jupyterlab-venv/lib64/python3.9/site-packages/jupyter_server/base/handlers.py", line 198, in logged_in
        user = self.current_user
      File "/home/ec2-user/environment/jupyterlab-venv/lib64/python3.9/site-packages/tornado/web.py", line 1424, in current_user
        self._current_user = self.get_current_user()
      File "/home/ec2-user/environment/jupyterlab-venv/lib64/python3.9/site-packages/jupyter_server/base/handlers.py", line 177, in get_current_user
        raise RuntimeError(msg)
    RuntimeError: Calling `Template404.get_current_user()` directly is deprecated in jupyter-server 2.0. Use `self.current_user` instead (works in all versions).
[W 2024-09-29 16:35:14.815 ServerApp] 405 CONNECT azenv.0889.org:443 (@144.91.103.52) 1.14ms referer=None
[I 2024-09-29 16:36:07.496 ServerApp] Saving file at /C2_W1_Lab_3_S3.ipynb
